<?xml version="1.0"?>
<robot name="bicycle_model">

  <gazebo>
    <static>False</static>
  </gazebo>

  <material name="grey">
    <color rgba="0.2 0.2 0.2 0.7"/>
  </material>

  <material name="black">
    <color rgba="0 0 0 0.7"/>
  </material>

  <material name="yellow">
    <color rgba="1 1 0 0.7"/>
  </material>


  <link name="dummy">
  </link>

  <link name="base_footprint">

    <inertial>
      <origin xyz="0 0 0"/>
      <mass value="1.0"/>
      <inertia ixx="1" ixy="0.0" ixz="0.0" iyy="1" iyz="0.0" izz="1"/>
    </inertial>

    <visual>
      <geometry>
        <box size="0.001 0.001 0.001"/>
      </geometry>
      <origin xyz="0 0 0" rpy="0 0 0"/>
    </visual>


  </link>


  <joint name="dummy_joint" type="fixed">
   <parent link="dummy"/>
   <child link="base_footprint"/>
  </joint>


  <link name="base_link">

    <inertial>
      <origin xyz="0 0 0"/>
      <mass value="212"/>
      <inertia ixx="1.4133" ixy="0.0" ixz="0.0" iyy="159.7" iyz="0.0" izz="159.7"/>
    </inertial>

    <visual>
      <geometry>
        <box size="3 0.2 0.2"/>
      </geometry>
      <origin rpy="0 0 0" xyz="0 0 0"/>
      <material name="yellow"/>
    </visual>

    <collision>
      <geometry>
        <box size="1 0.1 0.1"/>
      </geometry>
      <origin rpy="0 0 0" xyz="0 0 0"/>
    </collision>

  </link>

  <gazebo reference="base_link">
    <material>Gazebo/Yellow</material>
  </gazebo>


  <joint name="joint1" type="fixed">
    <parent link="base_footprint"/>
    <child link="base_link"/>
    <origin xyz="0 0 0.5" rpy="0 0 0"/>
  </joint>


  <link name="rear_wheel">

    <inertial>
      <origin xyz="0 0 0"/>
      <mass value="3.0"/>
      <inertia ixx="0.0525" ixy="0.0" ixz="0.0" iyy="0.0525" iyz="0.0" izz="0.06"/>
    </inertial>

    <visual>
      <geometry>
        <cylinder radius="0.2" length="0.2"/>
      </geometry>
      <origin xyz="0 0 0" rpy="1.57 0 0"/>
      <material name="black"/>
    </visual>

    <collision>
      <geometry>
        <cylinder radius="0.2" length="0.2"/>
      </geometry>
      <origin xyz="0 0 0" rpy="1.57 0 0"/>
    </collision>
  </link>


  <joint name="rear_wheel_joint" type="continuous">
    <parent link="base_link"/>
    <child link="rear_wheel"/>
    <origin xyz="-1.2 0 -0.3" rpy="0 0 0"/>
    <axis xyz="0 1 0"/>
  </joint>

  <transmission name="rear_wheel_trans">
    <type>transmission_interface/SimpleTransmission</type>
    <joint name="rear_wheel_joint">
      <hardwareInterface>hardware_interface/EffortJointInterface</hardwareInterface>
    </joint>
    <actuator name="rear_wheel_motor">
      <mechanicalReduction>50</mechanicalReduction>
      <hardwareInterface>hardware_interface/EffortJointInterface</hardwareInterface>
      <mechanicalReduction>1</mechanicalReduction>
    </actuator>
  </transmission>

  <gazebo reference="rear_wheel">
    <mu1 value="0.2"/>
    <mu2 value="0.2"/>
    <kp  value="10000000.0" />
    <kd  value="1.0" />
    <fdir1 value="1 0 0"/>
    <material>Gazebo/Black</material>
  </gazebo>


  <link name="front_wheel">

    <inertial>
      <origin xyz="0 0 0"/>
      <mass value="3.0"/>
      <inertia ixx="0.0525" ixy="0.0" ixz="0.0" iyy="0.0525" iyz="0.0" izz="0.06"/>
    </inertial>

    <visual>
      <geometry>
        <cylinder radius="0.2" length="0.2"/>
      </geometry>
      <origin xyz="0 0 0" rpy="1.57 0 0"/>
      <material name="black"/>
    </visual>

    <collision>
      <geometry>
        <cylinder radius="0.2" length="0.2"/>
      </geometry>
      <origin xyz="0 0 0" rpy="1.57 0 0"/>
    </collision>
  </link>


  <joint name="front_steer_joint" type="continuous">
    <parent link="base_link"/>
    <child link="front_wheel"/>
    <origin xyz="1.2 0 -0.3" rpy="0 0 0"/>
    <limit effort="10" velocity="3"/>
    <axis xyz="0 1 0"/>
  </joint>

  <transmission name="front_wheel_trans">
    <type>transmission_interface/SimpleTransmission</type>
    <joint name="front_steer_joint">
      <hardwareInterface>hardware_interface/EffortJointInterface</hardwareInterface>
    </joint>
    <actuator name="front_wheel_motor">
      <mechanicalReduction>50</mechanicalReduction>
      <hardwareInterface>hardware_interface/EffortJointInterface</hardwareInterface>
      <mechanicalReduction>1</mechanicalReduction>
    </actuator>
  </transmission>

  <gazebo reference="front_wheel">
    <mu1 value="0.2"/>
    <mu2 value="0.2"/>
    <kp  value="10000000.0" />
    <kd  value="1.0" />
    <fdir1 value="1 0 0"/>
    <material>Gazebo/Black</material>
  </gazebo>

  <!--gazebo>
    <plugin name="gazebo_ros_control" filename="libgazebo_ros_control.so">
      <robotNamespace>/bicycle_model</robotNamespace>
      <robotSimType>gazebo_ros_control/DefaultRobotHWSim</robotSimType>
    </plugin>
  </gazebo-->

  <gazebo>
    <plugin name="ackermann_steering_controller" filename="libackermann_steering_controller.so">
      <robotNamespace>/bicycle_model</robotNamespace>
      <!--robotSimType>ackermann_steering_controller/DefaultRobotHWSim</robotSimType-->
      <!--rosDebugLevel>Debug</rosDebugLevel>
      <publishWheelTF>false</publishWheelTF>
      <robotNamespace>/</robotNamespace>
      <publishTf>1</publishTf>
      <publishWheelJointState>false</publishWheelJointState>
      <alwaysOn>true</alwaysOn>
      <updateRate>100.0</updateRate>
      <fronSteer>front_steer_joint</frontSteer>
      <rearWheel>rear_wheel_joint</rearWheel>
      <broadcastTF>1</broadcastTF>
      <base_linkmandTopic>cmd_vel</base_linkmandTopic>
      <odometryFrame>odom</odometryFrame>
      <odometryTopic>odom</odometryTopic>
      <robotBaseFrame>base_link</robotBaseFrame-->


    </plugin>
  </gazebo>


</robot>
